{
 "cells": [
  {
   "cell_type": "code",
   "execution_count": 6,
   "id": "42a08d53-fcb1-43a2-900d-7a56072e9b41",
   "metadata": {
    "tags": []
   },
   "outputs": [
    {
     "name": "stdout",
     "output_type": "stream",
     "text": [
      "Epoch 1/5\n"
     ]
    },
    {
     "name": "stderr",
     "output_type": "stream",
     "text": [
      "2025-03-30 10:54:07.013531: W tensorflow/core/framework/op_kernel.cc:1857] OP_REQUIRES failed at sparse_xent_op.cc:103 : INVALID_ARGUMENT: Received a label value of 9 which is outside the valid range of [0, 5).  Label values: 2 1 8 4 1 9 2 2 0 2 6 9 0 7 5 4 0 1 8 0 4 2 6 7 0 6 4 0 3 1 2 7\n",
      "2025-03-30 10:54:07.013587: I tensorflow/core/framework/local_rendezvous.cc:407] Local rendezvous is aborting with status: INVALID_ARGUMENT: Received a label value of 9 which is outside the valid range of [0, 5).  Label values: 2 1 8 4 1 9 2 2 0 2 6 9 0 7 5 4 0 1 8 0 4 2 6 7 0 6 4 0 3 1 2 7\n",
      "\t [[{{function_node __inference_one_step_on_data_213823}}{{node compile_loss/sparse_categorical_crossentropy/SparseSoftmaxCrossEntropyWithLogits/SparseSoftmaxCrossEntropyWithLogits}}]]\n"
     ]
    },
    {
     "ename": "InvalidArgumentError",
     "evalue": "Graph execution error:\n\nDetected at node compile_loss/sparse_categorical_crossentropy/SparseSoftmaxCrossEntropyWithLogits/SparseSoftmaxCrossEntropyWithLogits defined at (most recent call last):\n  File \"/opt/conda/lib/python3.10/runpy.py\", line 196, in _run_module_as_main\n\n  File \"/opt/conda/lib/python3.10/runpy.py\", line 86, in _run_code\n\n  File \"/opt/conda/lib/python3.10/site-packages/ipykernel_launcher.py\", line 18, in <module>\n\n  File \"/opt/conda/lib/python3.10/site-packages/traitlets/config/application.py\", line 1075, in launch_instance\n\n  File \"/opt/conda/lib/python3.10/site-packages/ipykernel/kernelapp.py\", line 739, in start\n\n  File \"/opt/conda/lib/python3.10/site-packages/tornado/platform/asyncio.py\", line 205, in start\n\n  File \"/opt/conda/lib/python3.10/asyncio/base_events.py\", line 603, in run_forever\n\n  File \"/opt/conda/lib/python3.10/asyncio/base_events.py\", line 1909, in _run_once\n\n  File \"/opt/conda/lib/python3.10/asyncio/events.py\", line 80, in _run\n\n  File \"/opt/conda/lib/python3.10/site-packages/ipykernel/kernelbase.py\", line 545, in dispatch_queue\n\n  File \"/opt/conda/lib/python3.10/site-packages/ipykernel/kernelbase.py\", line 534, in process_one\n\n  File \"/opt/conda/lib/python3.10/site-packages/ipykernel/kernelbase.py\", line 437, in dispatch_shell\n\n  File \"/opt/conda/lib/python3.10/site-packages/ipykernel/ipkernel.py\", line 362, in execute_request\n\n  File \"/opt/conda/lib/python3.10/site-packages/ipykernel/kernelbase.py\", line 778, in execute_request\n\n  File \"/opt/conda/lib/python3.10/site-packages/ipykernel/ipkernel.py\", line 449, in do_execute\n\n  File \"/opt/conda/lib/python3.10/site-packages/ipykernel/zmqshell.py\", line 549, in run_cell\n\n  File \"/opt/conda/lib/python3.10/site-packages/IPython/core/interactiveshell.py\", line 3051, in run_cell\n\n  File \"/opt/conda/lib/python3.10/site-packages/IPython/core/interactiveshell.py\", line 3106, in _run_cell\n\n  File \"/opt/conda/lib/python3.10/site-packages/IPython/core/async_helpers.py\", line 129, in _pseudo_sync_runner\n\n  File \"/opt/conda/lib/python3.10/site-packages/IPython/core/interactiveshell.py\", line 3311, in run_cell_async\n\n  File \"/opt/conda/lib/python3.10/site-packages/IPython/core/interactiveshell.py\", line 3493, in run_ast_nodes\n\n  File \"/opt/conda/lib/python3.10/site-packages/IPython/core/interactiveshell.py\", line 3553, in run_code\n\n  File \"/var/tmp/ipykernel_94736/4233614800.py\", line 33, in <module>\n\n  File \"/opt/conda/lib/python3.10/site-packages/keras/src/utils/traceback_utils.py\", line 117, in error_handler\n\n  File \"/opt/conda/lib/python3.10/site-packages/keras/src/backend/tensorflow/trainer.py\", line 371, in fit\n\n  File \"/opt/conda/lib/python3.10/site-packages/keras/src/backend/tensorflow/trainer.py\", line 219, in function\n\n  File \"/opt/conda/lib/python3.10/site-packages/keras/src/backend/tensorflow/trainer.py\", line 132, in multi_step_on_iterator\n\n  File \"/opt/conda/lib/python3.10/site-packages/keras/src/backend/tensorflow/trainer.py\", line 113, in one_step_on_data\n\n  File \"/opt/conda/lib/python3.10/site-packages/keras/src/backend/tensorflow/trainer.py\", line 60, in train_step\n\n  File \"/opt/conda/lib/python3.10/site-packages/keras/src/trainers/trainer.py\", line 383, in _compute_loss\n\n  File \"/opt/conda/lib/python3.10/site-packages/keras/src/trainers/trainer.py\", line 351, in compute_loss\n\n  File \"/opt/conda/lib/python3.10/site-packages/keras/src/trainers/compile_utils.py\", line 690, in __call__\n\n  File \"/opt/conda/lib/python3.10/site-packages/keras/src/trainers/compile_utils.py\", line 699, in call\n\n  File \"/opt/conda/lib/python3.10/site-packages/keras/src/losses/loss.py\", line 67, in __call__\n\n  File \"/opt/conda/lib/python3.10/site-packages/keras/src/losses/losses.py\", line 33, in call\n\n  File \"/opt/conda/lib/python3.10/site-packages/keras/src/losses/losses.py\", line 2246, in sparse_categorical_crossentropy\n\n  File \"/opt/conda/lib/python3.10/site-packages/keras/src/ops/nn.py\", line 1964, in sparse_categorical_crossentropy\n\n  File \"/opt/conda/lib/python3.10/site-packages/keras/src/backend/tensorflow/nn.py\", line 744, in sparse_categorical_crossentropy\n\nReceived a label value of 9 which is outside the valid range of [0, 5).  Label values: 2 1 8 4 1 9 2 2 0 2 6 9 0 7 5 4 0 1 8 0 4 2 6 7 0 6 4 0 3 1 2 7\n\t [[{{node compile_loss/sparse_categorical_crossentropy/SparseSoftmaxCrossEntropyWithLogits/SparseSoftmaxCrossEntropyWithLogits}}]] [Op:__inference_multi_step_on_iterator_213864]",
     "output_type": "error",
     "traceback": [
      "\u001b[0;31m---------------------------------------------------------------------------\u001b[0m",
      "\u001b[0;31mInvalidArgumentError\u001b[0m                      Traceback (most recent call last)",
      "Cell \u001b[0;32mIn[6], line 33\u001b[0m\n\u001b[1;32m     29\u001b[0m \u001b[38;5;66;03m# Compile data\u001b[39;00m\n\u001b[1;32m     30\u001b[0m model\u001b[38;5;241m.\u001b[39mcompile(optimizer \u001b[38;5;241m=\u001b[39m tf\u001b[38;5;241m.\u001b[39mkeras\u001b[38;5;241m.\u001b[39moptimizers\u001b[38;5;241m.\u001b[39mAdam(),\n\u001b[1;32m     31\u001b[0m               loss \u001b[38;5;241m=\u001b[39m tf\u001b[38;5;241m.\u001b[39mkeras\u001b[38;5;241m.\u001b[39mlosses\u001b[38;5;241m.\u001b[39mSparseCategoricalCrossentropy(),\n\u001b[1;32m     32\u001b[0m               metrics\u001b[38;5;241m=\u001b[39m[tf\u001b[38;5;241m.\u001b[39mkeras\u001b[38;5;241m.\u001b[39mmetrics\u001b[38;5;241m.\u001b[39mSparseCategoricalAccuracy()])\n\u001b[0;32m---> 33\u001b[0m \u001b[43mmodel\u001b[49m\u001b[38;5;241;43m.\u001b[39;49m\u001b[43mfit\u001b[49m\u001b[43m(\u001b[49m\u001b[43mds_train\u001b[49m\u001b[43m,\u001b[49m\u001b[43m \u001b[49m\u001b[43mepochs\u001b[49m\u001b[38;5;241;43m=\u001b[39;49m\u001b[38;5;241;43m5\u001b[39;49m\u001b[43m)\u001b[49m\n\u001b[1;32m     34\u001b[0m \u001b[38;5;66;03m# Logs model summary\u001b[39;00m\n\u001b[1;32m     35\u001b[0m model\u001b[38;5;241m.\u001b[39msummary(print_fn\u001b[38;5;241m=\u001b[39mup_logger\u001b[38;5;241m.\u001b[39minfo)\n",
      "File \u001b[0;32m/opt/conda/lib/python3.10/site-packages/keras/src/utils/traceback_utils.py:122\u001b[0m, in \u001b[0;36mfilter_traceback.<locals>.error_handler\u001b[0;34m(*args, **kwargs)\u001b[0m\n\u001b[1;32m    119\u001b[0m     filtered_tb \u001b[38;5;241m=\u001b[39m _process_traceback_frames(e\u001b[38;5;241m.\u001b[39m__traceback__)\n\u001b[1;32m    120\u001b[0m     \u001b[38;5;66;03m# To get the full stack trace, call:\u001b[39;00m\n\u001b[1;32m    121\u001b[0m     \u001b[38;5;66;03m# `keras.config.disable_traceback_filtering()`\u001b[39;00m\n\u001b[0;32m--> 122\u001b[0m     \u001b[38;5;28;01mraise\u001b[39;00m e\u001b[38;5;241m.\u001b[39mwith_traceback(filtered_tb) \u001b[38;5;28;01mfrom\u001b[39;00m\u001b[38;5;250m \u001b[39m\u001b[38;5;28;01mNone\u001b[39;00m\n\u001b[1;32m    123\u001b[0m \u001b[38;5;28;01mfinally\u001b[39;00m:\n\u001b[1;32m    124\u001b[0m     \u001b[38;5;28;01mdel\u001b[39;00m filtered_tb\n",
      "File \u001b[0;32m/opt/conda/lib/python3.10/site-packages/tensorflow/python/eager/execute.py:53\u001b[0m, in \u001b[0;36mquick_execute\u001b[0;34m(op_name, num_outputs, inputs, attrs, ctx, name)\u001b[0m\n\u001b[1;32m     51\u001b[0m \u001b[38;5;28;01mtry\u001b[39;00m:\n\u001b[1;32m     52\u001b[0m   ctx\u001b[38;5;241m.\u001b[39mensure_initialized()\n\u001b[0;32m---> 53\u001b[0m   tensors \u001b[38;5;241m=\u001b[39m pywrap_tfe\u001b[38;5;241m.\u001b[39mTFE_Py_Execute(ctx\u001b[38;5;241m.\u001b[39m_handle, device_name, op_name,\n\u001b[1;32m     54\u001b[0m                                       inputs, attrs, num_outputs)\n\u001b[1;32m     55\u001b[0m \u001b[38;5;28;01mexcept\u001b[39;00m core\u001b[38;5;241m.\u001b[39m_NotOkStatusException \u001b[38;5;28;01mas\u001b[39;00m e:\n\u001b[1;32m     56\u001b[0m   \u001b[38;5;28;01mif\u001b[39;00m name \u001b[38;5;129;01mis\u001b[39;00m \u001b[38;5;129;01mnot\u001b[39;00m \u001b[38;5;28;01mNone\u001b[39;00m:\n",
      "\u001b[0;31mInvalidArgumentError\u001b[0m: Graph execution error:\n\nDetected at node compile_loss/sparse_categorical_crossentropy/SparseSoftmaxCrossEntropyWithLogits/SparseSoftmaxCrossEntropyWithLogits defined at (most recent call last):\n  File \"/opt/conda/lib/python3.10/runpy.py\", line 196, in _run_module_as_main\n\n  File \"/opt/conda/lib/python3.10/runpy.py\", line 86, in _run_code\n\n  File \"/opt/conda/lib/python3.10/site-packages/ipykernel_launcher.py\", line 18, in <module>\n\n  File \"/opt/conda/lib/python3.10/site-packages/traitlets/config/application.py\", line 1075, in launch_instance\n\n  File \"/opt/conda/lib/python3.10/site-packages/ipykernel/kernelapp.py\", line 739, in start\n\n  File \"/opt/conda/lib/python3.10/site-packages/tornado/platform/asyncio.py\", line 205, in start\n\n  File \"/opt/conda/lib/python3.10/asyncio/base_events.py\", line 603, in run_forever\n\n  File \"/opt/conda/lib/python3.10/asyncio/base_events.py\", line 1909, in _run_once\n\n  File \"/opt/conda/lib/python3.10/asyncio/events.py\", line 80, in _run\n\n  File \"/opt/conda/lib/python3.10/site-packages/ipykernel/kernelbase.py\", line 545, in dispatch_queue\n\n  File \"/opt/conda/lib/python3.10/site-packages/ipykernel/kernelbase.py\", line 534, in process_one\n\n  File \"/opt/conda/lib/python3.10/site-packages/ipykernel/kernelbase.py\", line 437, in dispatch_shell\n\n  File \"/opt/conda/lib/python3.10/site-packages/ipykernel/ipkernel.py\", line 362, in execute_request\n\n  File \"/opt/conda/lib/python3.10/site-packages/ipykernel/kernelbase.py\", line 778, in execute_request\n\n  File \"/opt/conda/lib/python3.10/site-packages/ipykernel/ipkernel.py\", line 449, in do_execute\n\n  File \"/opt/conda/lib/python3.10/site-packages/ipykernel/zmqshell.py\", line 549, in run_cell\n\n  File \"/opt/conda/lib/python3.10/site-packages/IPython/core/interactiveshell.py\", line 3051, in run_cell\n\n  File \"/opt/conda/lib/python3.10/site-packages/IPython/core/interactiveshell.py\", line 3106, in _run_cell\n\n  File \"/opt/conda/lib/python3.10/site-packages/IPython/core/async_helpers.py\", line 129, in _pseudo_sync_runner\n\n  File \"/opt/conda/lib/python3.10/site-packages/IPython/core/interactiveshell.py\", line 3311, in run_cell_async\n\n  File \"/opt/conda/lib/python3.10/site-packages/IPython/core/interactiveshell.py\", line 3493, in run_ast_nodes\n\n  File \"/opt/conda/lib/python3.10/site-packages/IPython/core/interactiveshell.py\", line 3553, in run_code\n\n  File \"/var/tmp/ipykernel_94736/4233614800.py\", line 33, in <module>\n\n  File \"/opt/conda/lib/python3.10/site-packages/keras/src/utils/traceback_utils.py\", line 117, in error_handler\n\n  File \"/opt/conda/lib/python3.10/site-packages/keras/src/backend/tensorflow/trainer.py\", line 371, in fit\n\n  File \"/opt/conda/lib/python3.10/site-packages/keras/src/backend/tensorflow/trainer.py\", line 219, in function\n\n  File \"/opt/conda/lib/python3.10/site-packages/keras/src/backend/tensorflow/trainer.py\", line 132, in multi_step_on_iterator\n\n  File \"/opt/conda/lib/python3.10/site-packages/keras/src/backend/tensorflow/trainer.py\", line 113, in one_step_on_data\n\n  File \"/opt/conda/lib/python3.10/site-packages/keras/src/backend/tensorflow/trainer.py\", line 60, in train_step\n\n  File \"/opt/conda/lib/python3.10/site-packages/keras/src/trainers/trainer.py\", line 383, in _compute_loss\n\n  File \"/opt/conda/lib/python3.10/site-packages/keras/src/trainers/trainer.py\", line 351, in compute_loss\n\n  File \"/opt/conda/lib/python3.10/site-packages/keras/src/trainers/compile_utils.py\", line 690, in __call__\n\n  File \"/opt/conda/lib/python3.10/site-packages/keras/src/trainers/compile_utils.py\", line 699, in call\n\n  File \"/opt/conda/lib/python3.10/site-packages/keras/src/losses/loss.py\", line 67, in __call__\n\n  File \"/opt/conda/lib/python3.10/site-packages/keras/src/losses/losses.py\", line 33, in call\n\n  File \"/opt/conda/lib/python3.10/site-packages/keras/src/losses/losses.py\", line 2246, in sparse_categorical_crossentropy\n\n  File \"/opt/conda/lib/python3.10/site-packages/keras/src/ops/nn.py\", line 1964, in sparse_categorical_crossentropy\n\n  File \"/opt/conda/lib/python3.10/site-packages/keras/src/backend/tensorflow/nn.py\", line 744, in sparse_categorical_crossentropy\n\nReceived a label value of 9 which is outside the valid range of [0, 5).  Label values: 2 1 8 4 1 9 2 2 0 2 6 9 0 7 5 4 0 1 8 0 4 2 6 7 0 6 4 0 3 1 2 7\n\t [[{{node compile_loss/sparse_categorical_crossentropy/SparseSoftmaxCrossEntropyWithLogits/SparseSoftmaxCrossEntropyWithLogits}}]] [Op:__inference_multi_step_on_iterator_213864]"
     ]
    }
   ],
   "source": [
    "# Import and configure logging\n",
    "import logging\n",
    "import google.cloud.logging as cloud_logging\n",
    "from google.cloud.logging.handlers import CloudLoggingHandler\n",
    "from google.cloud.logging_v2.handlers import setup_logging\n",
    "up_logger = logging.getLogger('upLogger')\n",
    "up_logger.setLevel(logging.INFO)\n",
    "up_logger.addHandler(CloudLoggingHandler(cloud_logging.Client(), name=\"updated\"))\n",
    "\n",
    "# Import tensorflow_datasets\n",
    "import tensorflow_datasets as tfds\n",
    "# Import numpy\n",
    "import numpy as np\n",
    "# Import TensorFlow\n",
    "import tensorflow as tf\n",
    "\n",
    "# Define, load and configure data\n",
    "(ds_train, ds_test), info = tfds.load('fashion_mnist', split=['train', 'test'], with_info=True, as_supervised=True)\n",
    "# Define batch size\n",
    "BATCH_SIZE = 32\n",
    "# Normalizing and batch processing of data\n",
    "ds_train = ds_train.batch(BATCH_SIZE)\n",
    "ds_test = ds_test.batch(BATCH_SIZE)\n",
    "# Define the model\n",
    "model = tf.keras.models.Sequential([tf.keras.layers.Flatten(),\n",
    "                                    tf.keras.layers.Dense(64, activation=tf.nn.relu),\n",
    "                                    tf.keras.layers.Dense(10, activation=tf.nn.softmax)])\n",
    "# Compile data\n",
    "model.compile(optimizer = tf.keras.optimizers.Adam(),\n",
    "              loss = tf.keras.losses.SparseCategoricalCrossentropy(),\n",
    "              metrics=[tf.keras.metrics.SparseCategoricalAccuracy()])\n",
    "model.fit(ds_train, epochs=5)\n",
    "# Logs model summary\n",
    "model.summary(print_fn=up_logger.info)\n",
    "\n",
    "# Print out max value to see the changes\n",
    "image_batch, labels_batch = next(iter(ds_train))\n",
    "t_image_batch, t_labels_batch = next(iter(ds_test))\n",
    "up_logger.info(\"training images max \" + str(np.max(image_batch[0])))\n",
    "up_logger.info(\"test images max \" + str(np.max(t_image_batch[0])))"
   ]
  },
  {
   "cell_type": "code",
   "execution_count": null,
   "id": "922e0029-2f2e-458f-861a-44c4c93e1b08",
   "metadata": {},
   "outputs": [],
   "source": []
  }
 ],
 "metadata": {
  "environment": {
   "kernel": "conda-base-py",
   "name": "workbench-notebooks.m129",
   "type": "gcloud",
   "uri": "us-docker.pkg.dev/deeplearning-platform-release/gcr.io/workbench-notebooks:m129"
  },
  "kernelspec": {
   "display_name": "Python 3 (ipykernel) (Local)",
   "language": "python",
   "name": "conda-base-py"
  },
  "language_info": {
   "codemirror_mode": {
    "name": "ipython",
    "version": 3
   },
   "file_extension": ".py",
   "mimetype": "text/x-python",
   "name": "python",
   "nbconvert_exporter": "python",
   "pygments_lexer": "ipython3",
   "version": "3.10.16"
  }
 },
 "nbformat": 4,
 "nbformat_minor": 5
}
